import logging

logging.error("エラーが発生しました")